<?xml version="1.0"?>
<robot xmlns:xacro="http://www.ros.org/wiki/xacro" name="wheel">

    <xacro:property name="length" value="0.02" />
    <xacro:property name="radius" value="0.08" />

    <xacro:macro name="wheel" params="prefix reflect_y">
        <link name="${prefix}_wheel">
            <visual>
                <geometry>
                    <cylinder length="${length}" radius="${radius}"/>
                </geometry>
                <origin rpy="1.5707 0 0"/>
            </visual>
            <collision>
                <geometry>
                    <cylinder length="${length}" radius="${radius}"/>
                </geometry>
                <origin rpy="1.5707 0 0"/>
            </collision>
            <inertial>
                <mass value="1"/>
                <inertia ixx="1.0" ixy="0.0" ixz="0.0" iyy="1.0" iyz="0.0" izz="1.0"/>
            </inertial>
        </link>

        <joint name="${prefix}_wheel_joint" type="continuous">
            <parent link="base_link"/>
            <child link="${prefix}_wheel"/>
            <origin xyz="0 ${reflect_y*0.2335} -0.05"/>
            <axis xyz="0.0 1.0 0.0"/>
        </joint>
        

    </xacro:macro>
</robot>