<?xml version="1.0"?>
<robot name="myfirst">

  <material name="blue">
    <color rgba="0 0 1 1"/>
  </material>
  <material name="black">
    <color rgba="0 0 0 1"/>
  </material>
  <material name="white">
    <color rgba="1 1 1 1"/>
  </material>

  <link name="base_link">
    <visual>
      <geometry>
        <box size="1.2 0.6 0.2"/>
      </geometry>
      <material name="blue"/>
    </visual>
    <collision>
     <geometry>
      <box size="1.2 0.6 0.2"/>
     </geometry>
    </collision>
    <inertial>
      <mass value="10"/>
      <inertia ixx="1.0" ixy="0.0" ixz="0.0" iyy="1.0" iyz="0.0" izz="1.0"/>
    </inertial>
  </link>


  <!--left_wheel-->

  <link name="left_wheel">
    <visual>
      <geometry>
        <cylinder length="0.02" radius="0.08"/>
      </geometry>
      <origin rpy="1.5707 0 0"/>
    </visual>
    <collision>
      <geometry>
        <cylinder length="0.02" radius="0.08"/>
      </geometry>
      <origin rpy="1.5707 0 0"/>
    </collision>
    <inertial>
      <mass value="1"/>
      <inertia ixx="1.0" ixy="0.0" ixz="0.0" iyy="1.0" iyz="0.0" izz="1.0"/>
    </inertial>
  </link>

  <joint name="joint_left_wheel" type="fixed">
    <parent link="base_link"/>
    <child link="left_wheel"/>
    <origin xyz="0 0.2335 -0.05"/>
  </joint>

  <!--right_wheel-->

  <link name="right_wheel">
    <visual>
      <geometry>
        <cylinder length="0.02" radius="0.08"/>
      </geometry>
      <origin rpy="1.5707 0 0"/>
    </visual>
    <collision>
      <geometry>
        <cylinder length="0.02" radius="0.08"/>
      </geometry>
      <origin rpy="1.5707 0 0"/>
    </collision>
    <inertial>
      <mass value="1"/>
      <inertia ixx="1.0" ixy="0.0" ixz="0.0" iyy="1.0" iyz="0.0" izz="1.0"/>
    </inertial>
  </link>

  <joint name="joint_right_wheel" type="continuous">
    <axis rpy="0 0 0" xyz="0 1 0"/>
    <parent link="base_link"/>
    <child link="right_wheel"/>
    <origin xyz="0 -0.2335 -0.05"/>
  </joint>


  <!--left_back_caster_wheel-->

  <link name="left_back_caster_wheel">
    <visual>
      <geometry>
        <cylinder length="0.03" radius="0.04"/>
      </geometry>
      <origin rpy="1.5707 0 0"/>
    </visual>
    <collision>
      <geometry>
        <cylinder length="0.03" radius="0.04"/>
      </geometry>
      <origin rpy="1.5707 0 0"/>
    </collision>
    <inertial>
      <mass value="0.5"/>
      <inertia ixx="1.0" ixy="0.0" ixz="0.0" iyy="1.0" iyz="0.0" izz="1.0"/>
    </inertial>
  </link>

  <joint name="joint_left_back_caster_wheel" type="fixed">
    <parent link="left_back_holder"/>
    <child link="left_back_caster_wheel"/>
    <origin xyz="-0.0565 0 -0.0565"/>
  </joint>

                <!-- left_back_holder -->

  <link name="left_back_holder">
    <visual>
      <geometry>
        <box size="0.02 0.08 0.01"/>
      </geometry>
      <origin rpy="1.5707 0.7853 0" xyz="-0.0283 0.0 -0.0283"/>
    </visual>
    <collision>
      <geometry>
        <box size="0.02 0.08 0.01"/>
      </geometry>
      <origin rpy="1.5707 0.7853 0" xyz="-0.0283 0.0 -0.0283"/>
    </collision>
    <inertial>
      <mass value="0.2"/>
      <inertia ixx="1.0" ixy="0.0" ixz="0.0" iyy="1.0" iyz="0.0" izz="1.0"/>
    </inertial>
  </link>

  <joint name="left_back_holder" type="continuous">
    <axis rpy="0 0 0" xyz="0 0 1"/>
    <parent link="left_back_fix_holder"/>
    <child link="left_back_holder"/>
    <origin xyz="0 0 0"/>
  </joint>  

          <!-- left_back_fix holder -->

  <link name="left_back_fix_holder">
    <visual>
      <geometry>
        <box size="0.04 0.04 0.01"/>
      </geometry>
      <origin rpy="0 0 0" xyz="0 0 0"/>
    </visual>
    <collision>
      <geometry>
        <box size="0.04 0.04 0.01"/>
      </geometry>
      <origin rpy="0 0 0" xyz="0 0 0"/>
    </collision>
    <inertial>
      <mass value="0.2"/>
      <inertia ixx="1.0" ixy="0.0" ixz="0.0" iyy="1.0" iyz="0.0" izz="1.0"/>
    </inertial>
  </link>

  <joint name="joint_left_back_fix_holder" type="fixed">
    <parent link="base_link"/>
    <child link="left_back_fix_holder"/>
    <origin xyz="-0.3749 0.170 -0.0335"/>
  </joint> 




  <!--right_back_caster_wheel-->

  <link name="right_back_caster_wheel">
    <visual>
      <geometry>
        <cylinder length="0.03" radius="0.04"/>
      </geometry>
      <origin rpy="1.5707 0 0"/>
    </visual>
    <collision>
      <geometry>
        <cylinder length="0.03" radius="0.04"/>
      </geometry>
      <origin rpy="1.5707 0 0"/>
    </collision>
    <inertial>
      <mass value="0.5"/>
      <inertia ixx="1.0" ixy="0.0" ixz="0.0" iyy="1.0" iyz="0.0" izz="1.0"/>
    </inertial>
  </link>

  <joint name="joint_right_back_caster_wheel" type="fixed">
    <parent link="right_back_holder"/>
    <child link="right_back_caster_wheel"/>
    <origin xyz="-0.0565 0 -0.0565"/>
  </joint>

              <!-- right_back_holder -->

  <link name="right_back_holder">
    <visual>
      <geometry>
        <box size="0.02 0.08 0.01"/>
      </geometry>
      <origin rpy="1.5707 0.7853 0" xyz="-0.0283 0.0 -0.0283"/>
    </visual>
    <collision>
      <geometry>
        <box size="0.02 0.08 0.01"/>
      </geometry>
      <origin rpy="1.5707 0.7853 0" xyz="-0.0283 0.0 -0.0283"/>
    </collision>
    <inertial>
      <mass value="0.2"/>
      <inertia ixx="1.0" ixy="0.0" ixz="0.0" iyy="1.0" iyz="0.0" izz="1.0"/>
    </inertial>
  </link>

  <joint name="right_back_holder" type="continuous">
    <axis rpy="0 0 0" xyz="0 0 1"/>
    <parent link="right_back_fix_holder"/>
    <child link="right_back_holder"/>
    <origin xyz="0 0 0"/>
  </joint>  

          <!-- right_back_fix holder -->

  <link name="right_back_fix_holder">
    <visual>
      <geometry>
        <box size="0.04 0.04 0.01"/>
      </geometry>
      <origin rpy="0 0 0" xyz="0 0 0"/>
    </visual>
    <collision>
      <geometry>
        <box size="0.04 0.04 0.01"/>
      </geometry>
      <origin rpy="0 0 0" xyz="0 0 0"/>
    </collision>
    <inertial>
      <mass value="0.2"/>
      <inertia ixx="1.0" ixy="0.0" ixz="0.0" iyy="1.0" iyz="0.0" izz="1.0"/>
    </inertial>
  </link>

  <joint name="joint_right_back_fix_holder" type="fixed">
    <parent link="base_link"/>
    <child link="right_back_fix_holder"/>
    <origin xyz="-0.3749 -0.170 -0.0335"/>
  </joint> 


  <!--left_front_caster_wheel-->

  <link name="left_front_caster_wheel">
    <visual>
      <geometry>
        <cylinder length="0.03" radius="0.04"/>
      </geometry>
      <origin rpy="1.5707 0 0"/>
    </visual>
    <collision>
      <geometry>
        <cylinder length="0.03" radius="0.04"/>
      </geometry>
      <origin rpy="1.5707 0 0"/>
    </collision>
    <inertial>
      <mass value="0.5"/>
      <inertia ixx="1.0" ixy="0.0" ixz="0.0" iyy="1.0" iyz="0.0" izz="1.0"/>
    </inertial>
  </link>

  <joint name="joint_left_front_caster_wheel" type="fixed">
    <parent link="left_front_holder"/>
    <child link="left_front_caster_wheel"/>
    <origin xyz="0.0565 0 -0.0565"/>
  </joint>

            <!-- left_front_holder -->

  <link name="left_front_holder">
    <visual>
      <geometry>
        <box size="0.02 0.08 0.01"/>
      </geometry>
      <origin rpy="1.5707 -0.7853 0" xyz="0.0283 0.0 -0.0283"/>
    </visual>
    <collision>
      <geometry>
        <box size="0.02 0.08 0.01"/>
      </geometry>
      <origin rpy="1.5707 -0.7853 0" xyz="0.0283 0.0 -0.0283"/>
    </collision>
    <inertial>
      <mass value="0.2"/>
      <inertia ixx="1.0" ixy="0.0" ixz="0.0" iyy="1.0" iyz="0.0" izz="1.0"/>
    </inertial>
  </link>

  <joint name="joint_left_front_holder" type="continuous">
    <axis rpy="0 0 0" xyz="0 0 1"/>
    <parent link="left_front_fix_holder"/>
    <child link="left_front_holder"/>
    <origin xyz="0 0 0"/>
  </joint>  

          <!-- left_front_fix holder -->

  <link name="left_front_fix_holder">
    <visual>
      <geometry>
        <box size="0.04 0.04 0.01"/>
      </geometry>
      <origin rpy="0 0 0" xyz="0 0 0"/>
    </visual>
    <collision>
      <geometry>
        <box size="0.04 0.04 0.01"/>
      </geometry>
      <origin rpy="0 0 0" xyz="0 0 0"/>
    </collision>
    <inertial>
      <mass value="0.2"/>
      <inertia ixx="1.0" ixy="0.0" ixz="0.0" iyy="1.0" iyz="0.0" izz="1.0"/>
    </inertial>
  </link>

  <joint name="joint_left_front_fix_holder" type="fixed">
    <parent link="base_link"/>
    <child link="left_front_fix_holder"/>
    <origin xyz="0.3749 0.170 -0.0335"/>
  </joint> 


  <!--right_front_caster_wheel-->

  <link name="right_front_caster_wheel">
    <visual>
      <geometry>
        <cylinder length="0.03" radius="0.04"/>
      </geometry>
      <origin rpy="1.5707 0 0"/>
    </visual>
    <collision>
      <geometry>
        <cylinder length="0.03" radius="0.04"/>
      </geometry>
      <origin rpy="1.5707 0 0"/>
    </collision>
    <inertial>
      <mass value="0.5"/>
      <inertia ixx="1.0" ixy="0.0" ixz="0.0" iyy="1.0" iyz="0.0" izz="1.0"/>
    </inertial>
  </link>

  <joint name="joint_right_front_caster_wheel" type="continuous">
    <axis rpy="0 0 0" xyz="0 1 0"/>
    <parent link="right_front_holder"/>
    <child link="right_front_caster_wheel"/>
    <origin xyz="0.0565 0 -0.0565"/>
  </joint>  

          <!-- right_front_holder -->

  <link name="right_front_holder">
    <visual>
      <geometry>
        <box size="0.02 0.08 0.01"/>
      </geometry>
      <origin rpy="1.5707 -0.7853 0" xyz="0.0283 0.0 -0.0283"/>
    </visual>
    <collision>
      <geometry>
        <box size="0.02 0.08 0.01"/>
      </geometry>
      <origin rpy="1.5707 -0.7853 0" xyz="0.0283 0.0 -0.0283"/>
    </collision>
    <inertial>
      <mass value="0.2"/>
      <inertia ixx="1.0" ixy="0.0" ixz="0.0" iyy="1.0" iyz="0.0" izz="1.0"/>
    </inertial>
  </link>

  <joint name="joint_right_front_holder" type="continuous">
    <axis rpy="0 0 0" xyz="0 0 1"/>
    <parent link="right_front_fix_holder"/>
    <child link="right_front_holder"/>
    <origin xyz="0 0 0"/>
  </joint>  

          <!-- right_front_fix holder -->

  <link name="right_front_fix_holder">
    <visual>
      <geometry>
        <box size="0.04 0.04 0.01"/>
      </geometry>
      <origin rpy="0 0 0" xyz="0 0 0"/>
    </visual>
    <collision>
      <geometry>
        <box size="0.04 0.04 0.01"/>
      </geometry>
      <origin rpy="0 0 0" xyz="0 0 0"/>
    </collision>
    <inertial>
      <mass value="0.2"/>
      <inertia ixx="1.0" ixy="0.0" ixz="0.0" iyy="1.0" iyz="0.0" izz="1.0"/>
    </inertial>
  </link>

  <joint name="joint_right_front_fix_holder" type="fixed">
    <parent link="base_link"/>
    <child link="right_front_fix_holder"/>
    <origin xyz="0.3749 -0.170 -0.0335"/>
  </joint> 

  
</robot>

