<?xml version="1.0"?>

<robot xmlns:xacro="http://www.ros.org/wiki/xacro" name="caster_wheel_holder">
    <xacro:macro name="caster_wheel_holder" params="prefix reflect reflect_x">
        <link name="${prefix}_wheel_holder">
            <visual>
                <origin rpy="0 0 1.57" xyz="0 0.0 0"/>
                <geometry>
                    <mesh filename="package://diffamr_description/meshes/caster_wheel/caster_wheel_holder.stl" scale="0.001 0.001 0.001"/>
                </geometry>
                <material name="white"/>
            </visual>
            <collision>
                <origin rpy="0 0 1.57" xyz="0 0 0"/>
                <geometry>
                    <mesh filename="package://diffamr_description/meshes/caster_wheel/caster_wheel_holder.stl" scale="0.001 0.001 0.001"/>
                </geometry>
            </collision>
            <inertial>
                <origin rpy="0 0 0" xyz="-0.016128780082706073 0.00014179777503836588 -0.025444393443257315"/>
                <mass value="1.183936664781352"/>
                <inertia ixx="0.001551" ixy="5e-06" ixz="-0.00043" iyy="0.001434" iyz="5e-06" izz="0.001853"/>
            </inertial>
        </link>
        
        <joint name="${prefix}_wheel_holder_joint" type="continuous">
            <axis xyz="0 0 1.0"/>
            <parent link="${prefix}_top_flat"/>
            <child link="${prefix}_wheel_holder"/>
            <origin rpy="0 0 0" xyz="0 0 -0.014"/>
            <dynamics friction="0.0015"/>
        </joint>
    </xacro:macro>
</robot>